<!--
  Dragonbot — TidyBot mobile base + YAM arm (6-DOF) + Aero Hand Right (16-DOF).

  Replaces the Kinova Gen3 arm and 2F85 gripper from the original TidyBot
  (stanford_tidybot/tidybot.xml) with the YAM arm and TetherIA Aero Hand.

  Asset paths:
    Base meshes  : ../assets/base/     (models/assets/base/)
    YAM meshes   : absolute path → i2rt/i2rt/robot_models/yam/assets/
    Aero Hand    : loaded via <model>, meshes resolved relative to right_hand.xml
-->
<mujoco model="dragonbot">
  <compiler angle="radian" meshdir="../assets"/>

  <option integrator="implicitfast"/>
  <option cone="elliptic" impratio="10"/>

  <!-- ── Default classes ──────────────────────────────────────────────────── -->
  <default>
    <!-- Mobile base -->
    <default class="base">
      <default class="base/visual">
        <geom type="mesh" contype="0" conaffinity="0" group="2"/>
      </default>
      <default class="base/collision">
        <geom type="mesh" group="3"/>
      </default>
    </default>

    <!-- YAM arm -->
    <default class="yam">
      <default class="yam/visual">
        <geom type="mesh" contype="0" conaffinity="0" group="2" rgba="1 0.6 0 1"/>
      </default>
      <default class="yam/collision">
        <geom type="mesh" group="3" rgba="1 0.6 0 0.3"/>
      </default>
      <default class="yam/actuator">
        <position kp="500" kv="50" forcerange="-10 10"/>
      </default>
    </default>

    <site size="0.001" rgba="0.5 0.5 0.5 0.3" group="4"/>
  </default>

  <!-- ── Assets ───────────────────────────────────────────────────────────── -->
  <asset>
    <!-- Base materials -->
    <material name="black"     rgba="0.11372549 0.11372549 0.10196078 1"/>
    <material name="gray"      rgba="0.62745098 0.65098039 0.64705882 1"/>
    <material name="dark_gray" rgba="0.35294118 0.37647059 0.37254902 1"/>

    <!-- Base meshes (relative to meshdir="../assets") -->
    <mesh file="base/bumper.stl"/>
    <mesh file="base/bottom_plate.stl"/>
    <mesh file="base/body.stl"/>
    <mesh file="base/top_plate.stl"/>
    <mesh file="base/arm_plate.stl"/>

    <!-- YAM arm meshes (absolute — not yet in models/assets) -->
    <mesh name="yam/base_link" file="/home/dragonx/tetheria/i2rt/i2rt/robot_models/yam/assets/base_link_collision.stl"/>
    <mesh name="yam/link_1"    file="/home/dragonx/tetheria/i2rt/i2rt/robot_models/yam/assets/link_1_collision.stl"/>
    <mesh name="yam/link_2"    file="/home/dragonx/tetheria/i2rt/i2rt/robot_models/yam/assets/link_2_collision.stl"/>
    <mesh name="yam/link_3"    file="/home/dragonx/tetheria/i2rt/i2rt/robot_models/yam/assets/link_3_collision.stl"/>
    <mesh name="yam/link_4"    file="/home/dragonx/tetheria/i2rt/i2rt/robot_models/yam/assets/link_4_collision.stl"/>
    <mesh name="yam/link_5"    file="/home/dragonx/tetheria/i2rt/i2rt/robot_models/yam/assets/link_5_collision.stl"/>
    <mesh name="yam/link_6"    file="/home/dragonx/tetheria/i2rt/i2rt/robot_models/yam/assets/link_6_collision.stl"/>

    <!-- Aero Hand — loads its own meshes relative to right_hand.xml -->
    <model name="aero_hand"
           file="/home/dragonx/tetheria/mujoco_menagerie/tetheria_aero_hand_open/right_hand.xml"/>
  </asset>

  <!-- ── Kinematic tree ───────────────────────────────────────────────────── -->
  <worldbody>

    <!-- ── Mobile base (3-DOF: x, y, θ) ──────────────────────────────────── -->
    <body name="base_link">
      <inertial pos="0 0 0.035" mass="60" diaginertia="0.001 0.001 0.001"/>
      <joint name="joint_x"  type="slide" axis="1 0 0"/>
      <joint name="joint_y"  type="slide" axis="0 1 0"/>
      <joint name="joint_th" type="hinge" axis="0 0 1"/>

      <!-- Visual + collision meshes (from models/assets/base/) -->
      <geom class="base/visual"    mesh="bumper"       material="black"/>
      <geom class="base/visual"    mesh="bottom_plate" material="dark_gray"/>
      <geom class="base/visual"    mesh="body"         material="gray"/>
      <geom class="base/visual"    mesh="top_plate"    material="dark_gray"/>
      <geom class="base/visual"    mesh="arm_plate"    material="gray"/>
      <geom class="base/collision" mesh="bumper"/>
      <geom class="base/collision" mesh="bottom_plate"/>
      <geom class="base/collision" mesh="body"/>
      <geom class="base/collision" mesh="top_plate"/>
      <geom class="base/collision" mesh="arm_plate"/>

      <!-- Forward-facing base camera -->
      <camera name="base_cam" pos="0.2525 0 0.335"
              euler="0 -0.7853981634 -1.5707963268"
              fovy="52.23" resolution="640 360"/>

      <!-- ── YAM arm mount (replaces gen3/base_link) ──────────────────────── -->
      <!-- Mounted at the same height (0.335 m) as the original Gen3 arm.      -->
      <!-- The static YAM base-plate geom sits just below the arm joints.      -->
      <body name="yam_mount" pos="0 0 0.335" quat="1 0 0 0">
        <inertial pos="0 0 0.02" mass="0.5" diaginertia="0.001 0.001 0.001"/>
        <!-- YAM base plate (cosmetic) -->
        <geom class="yam/visual" mesh="yam/base_link"
              pos="-7.22812e-05 2.52572e-05 0.0159932" quat="1 0 0 0"/>

        <!-- ── YAM arm kinematic chain (6-DOF) ──────────────────────────── -->
        <body name="link_1" pos="0 0 0.0631" quat="1 0 0 1">
          <inertial pos="-0.00192861 -0.00795735 0.0208176"
                    quat="0.297851 0.642634 0.360045 0.607185"
                    mass="0.12415" diaginertia="0.000180751 0.000145532 5.89179e-05"/>
          <joint name="joint1" pos="0 0 0" axis="0 0 1"
                 range="-2.61799 3.13" armature="0.01" damping="1"/>
          <geom class="yam/visual" mesh="yam/link_1"
                pos="-0.00192861 -0.00795735 0.0208176"
                quat="0.707105 0 0 -0.707108"/>

          <body name="link_2" pos="2.5e-05 -0.02 0.0409" quat="1 1 1 1">
            <inertial pos="0.132008 2.10599e-06 0.000293073"
                      quat="1 1 1 1" mass="1.24434"
                      diaginertia="0.0121902 0.0121318 0.000683304"/>
            <joint name="joint2" pos="0 0 0" axis="0 0 1"
                   range="0 3.65" armature="0.01" damping="1"/>
            <geom class="yam/visual" mesh="yam/link_2"
                  pos="0.132008 2.10599e-06 0.000293073"
                  quat="9.38184e-07 9.38187e-07 0.707108 0.707105"/>

            <body name="link_3" pos="0.264 0 0" quat="0 1 0 0">
              <inertial pos="-0.121816 -0.054846 -0.000111108"
                        quat="1 1 1 1" mass="0.853698"
                        diaginertia="0.00699732 0.00696112 0.000788244"/>
              <joint name="joint3" pos="0 0 0" axis="0 0 1"
                     range="0 3.13" armature="0.01" damping="1"/>
              <geom class="yam/visual" mesh="yam/link_3"
                    pos="-0.121816 -0.054846 -0.000111108"
                    quat="9.38184e-07 -9.38187e-07 0.707108 -0.707105"/>

              <body name="link_4" pos="-0.245 -0.06 0" quat="1 0 0 0">
                <inertial pos="-0.0769778 -0.0527104 0.000154878"
                          quat="0.667 0.667 -0.236 -0.236" mass="0.463511"
                          diaginertia="0.000791532 0.000744733 0.000282116"/>
                <joint name="joint4" pos="0 0 0" axis="0 0 1"
                       range="-1.65 1.65" armature="0.01" damping="1"/>
                <geom class="yam/visual" mesh="yam/link_4"
                      pos="-0.0569778 -0.0527104 0.000154878"
                      quat="9.38184e-07 -9.38187e-07 0.707108 -0.707105"/>

                <body name="link_5" pos="-0.074 -0.0395 2.5e-05" quat="1 -1 1 1">
                  <inertial pos="3.64861e-05 0.00025665 0.0353526"
                            quat="1 0 0 0" mass="0.350962"
                            diaginertia="0.000197802 0.0001775 0.000147402"/>
                  <joint name="joint5" pos="0 0 0" axis="0 0 1"
                         range="-1.5708 1.5708" armature="0.01" damping="1"/>
                  <geom class="yam/visual" mesh="yam/link_5"
                        pos="3.64861e-05 0.00025665 0.0353526"
                        quat="9.38184e-07 -0.707105 -0.707108 9.38187e-07"/>

                  <body name="link_6" pos="0 0.0353 0.0395" quat="1 -1 0 0">
                    <inertial pos="-5.10177e-05 -0.00269952 0.0581778"
                              quat="0.98383 0.174699 0.0 0.0" mass="0.55366"
                              diaginertia="0.000956992 0.000799286 0.000469547"/>
                    <joint name="joint6" pos="0 0 0" axis="0 0 1"
                           range="-2.0944 2.0944" armature="0.01" damping="1"/>
                    <geom class="yam/visual" mesh="yam/link_6"
                          pos="-5.10177e-05 -0.00269952 0.0481778"
                          quat="1 -1 -1 -1"/>
                    <site name="tcp_site"   pos="0 0 0"      quat="1 0 0 -1"
                          size="0.006" rgba="1 0 0 1"/>
                    <site name="grasp_site" pos="0 0 0.1347" quat="1 0 0 -1"
                          size="0.006" rgba="0 1 0 1"/>
                    <!-- Wrist camera facing along the tool axis -->
                    <camera name="wrist_cam" pos="0 0 0.05" quat="1 0 0 -1"
                            fovy="60" resolution="640 480"/>

                    <!-- ── Aero Hand attached at wrist ──────────────────── -->
                    <!-- hand_ prefix applied to all bodies/joints/sites.    -->
                    <attach model="aero_hand" body="tetheria_mount" prefix="hand_"/>

                  </body>  <!-- link_6 -->
                </body>  <!-- link_5 -->
              </body>  <!-- link_4 -->
            </body>  <!-- link_3 -->
          </body>  <!-- link_2 -->
        </body>  <!-- link_1 -->

      </body>  <!-- yam_mount -->
    </body>  <!-- base_link -->

  </worldbody>

  <!-- ── Actuators ────────────────────────────────────────────────────────── -->
  <actuator>
    <!-- Mobile base — high-gain position hold (velocity commands integrated externally) -->
    <position name="act_x"  joint="joint_x"  kp="1000000" kv="50000"/>
    <position name="act_y"  joint="joint_y"  kp="1000000" kv="50000"/>
    <position name="act_th" joint="joint_th" kp="50000"   kv="1000"/>

    <!-- YAM arm — position control, ±10 N·m force limit -->
    <position class="yam/actuator" name="act_joint1" joint="joint1"
              ctrlrange="-2.61799 3.13"/>
    <position class="yam/actuator" name="act_joint2" joint="joint2"
              ctrlrange="0 3.65"/>
    <position class="yam/actuator" name="act_joint3" joint="joint3"
              ctrlrange="0 3.13"/>
    <position class="yam/actuator" name="act_joint4" joint="joint4"
              ctrlrange="-1.65 1.65"/>
    <position class="yam/actuator" name="act_joint5" joint="joint5"
              ctrlrange="-1.5708 1.5708"/>
    <position class="yam/actuator" name="act_joint6" joint="joint6"
              ctrlrange="-2.0944 2.0944"/>
  </actuator>

  <!-- Keyframes: zero = base at origin, arm at zero-joint config -->
  <keyframe>
    <key name="home" qpos="0 0 0  0 0 0 0 0 0
                           0 0 0 0 0 0 0 0 0 0 0 0 0 0 0 0 0 0 0 0"
         ctrl="0 0 0  0 0 0 0 0 0"/>
  </keyframe>

</mujoco>
